tests/mediumHard/mediumHard_23.in
15
o
0 B 101 FEG 105 622
1 S 102 GORN 1547 623
0 S 103 AAM 1355 212
0 S 104 BDD 1566 618
8 S 106 GEGS 1752 242
6 B 107 CAE 1924 741
1 S 109 AAIN 1865 513
0 B 110 STRA 1923 121
9 B 112 CAE 162 454
6 C 107
1 C 109
3 B 115 GORN 1987 951
7 B 116 AAIN 398 379
2 B 117 AAIE 840 569
8 S 118 STRIPE 1296 948
9 S 119 HAHEOD 594 819
3 S 120 CONC 1241 444
9 B 121 STRA 1252 90
9 S 122 GORN 1109 304
8 C 118
12 S 124 THRONE 225 356
8 S 125 AAN 183 439
1 C 109
1 B 127 A 753 896
6 C 107
3 S 129 AAM 1668 118
0 C 101
8 S 131 GORN 731 266
0 S 132 CAE 413 579
8 B 133 AAIE 1353 526
14 S 135 AAID 1291 912
6 S 136 AAO 125 270
9 C 122
6 S 139 GORN 1248 603
13 S 140 AAIC 1051 511
14 C 135
7 C 116
10 B 144 AAM 1743 872
2 S 145 CONC 1263 875
5 S 146 BDD 790 563
11 B 147 AAC 418 174
5 S 148 STRIPE 736 228
1 C 127
14 C 135
11 S 151 AA 1738 379
4 S 152 AAIE 1857 181
14 C 135
9 B 154 AA 1423 235
11 S 155 CONC 1956 421
5 B 156 GEGS 1392 718
0 S 157 AAIN 833 246
2 B 158 GORN 417 356
5 B 159 GORN 595 68
7 C 116
13 B 161 AAIC 996 294
5 C 146
5 C 156
10 C 144
1 B 165 AAO 1159 840
8 B 166 THRONE 678 566
5 C 146
5 B 168 A 1270 544
7 C 116
14 C 135
10 S 171 HAHEOD 1124 863
14 S 172 STRA 285 220
6 C 107
14 S 174 AA 842 253
8 S 175 A 949 795
8 C 106
3 S 177 CONC 1244 802
14 B 178 AAO 1350 665
10 B 179 AAO 1642 262
12 C 124
0 C 132
11 C 151
5 B 183 AAC 511 272
11 S 184 GORN 1425 895
10 S 185 AA 1575 673
14 S 186 GORN 546 82
3 S 187 HAHEOD 1798 932
6 C 107
4 C 152
0 S 190 STRA 627 364
13 C 161
5 S 192 AAIE 1839 839
9 C 112
2 B 194 GEGS 1089 266
6 B 195 AAN 1036 198
5 B 196 GORN 1625 818
14 C 178
7 C 116
11 B 199 CONC 1032 727
5 S 200 GORN 714 376
4 B 201 AAM 744 477
3 C 177
9 C 122
10 C 185
4 S 205 GORN 634 945
10 S 206 GORN 1132 655
14 S 207 AAN 231 860
2 S 208 A 1087 322
9 C 119
8 C 166
7 B 211 HAHEOD 820 37
4 B 212 VIDE 1989 672
12 C 124
5 B 214 DOOR 564 362
6 C 107
12 S 216 AAM 1896 450
12 S 217 GEGS 1657 673
2 S 218 STRIPE 1819 166
6 C 139
0 C 157
5 B 221 AA 1805 360
5 B 222 AAID 1158 570
8 B 223 FEG 1968 920
9 S 224 VIDE 1968 475
5 S 225 A 934 895
14 S 226 GORN 1668 68
3 S 227 AAIE 1769 137
7 B 228 AAIN 1106 928
4 C 212
11 S 230 AAIN 832 588
9 S 231 AA 1541 165
6 B 232 AA 1856 717
5 S 233 FEG 1386 334
2 S 234 AAC 1754 297
14 B 235 GORN 1141 623
5 B 236 AAO 1852 176
0 C 157
6 S 238 AAO 1250 289
5 C 225
4 B 240 AAO 1830 384
11 S 241 GLIN 1885 785
13 C 140
9 S 243 A 588 977
3 B 244 GLIN 1789 963
9 B 245 CAE 332 773
5 S 246 AAIE 455 260
6 S 247 GORN 1509 448
5 C 225
5 B 249 CAE 1358 446
1 C 109
6 B 251 FEG 120 737
8 S 252 AA 1457 534
4 C 212
0 C 157
10 C 206
11 C 230
8 C 106
8 S 258 AAC 365 952
4 B 259 HAHEOD 713 341
14 S 260 GORN 1883 538
1 S 261 STRA 157 97
12 S 262 CAE 948 872
7 B 263 FEG 1793 778
11 B 264 FEG 923 816
7 S 265 BDD 216 167
14 S 266 DOOR 1122 211
0 B 267 AAIE 769 700
2 C 158
7 B 269 AAM 1112 578
4 S 270 DOOR 1529 35
4 S 271 STRIPE 1544 264
7 B 272 AAN 1969 547
8 S 273 AAC 726 137
4 C 259
12 S 275 VIDE 701 739
10 C 144
3 B 277 GEGS 1729 800
10 B 278 AAN 298 277
9 S 279 STRIPE 334 799
8 C 175
13 C 140
11 S 282 GEGS 352 37
2 B 283 GORN 294 661
4 C 212
12 C 275
2 B 286 GORN 545 840
2 S 287 AAN 1191 161
2 C 194
11 B 289 STRA 1585 677
1 S 290 BDD 414 891
10 C 278
8 C 252
6 S 293 BDD 1605 671
12 S 294 HAHEOD 1986 220
10 B 295 AAID 1343 962
8 B 296 AAO 302 895
13 S 297 AAC 1607 266
6 S 298 AAIE 547 397
9 B 299 AAC 638 417
11 B 300 THRONE 1104 239
2 S 301 GORN 1110 168
8 C 296
3 B 303 AAO 955 397
1 C 109
12 S 305 HAHEOD 1905 295
7 C 272
14 C 186
4 S 308 AAC 185 659
3 B 309 AAIC 888 999
5 S 310 STRA 613 49
7 B 311 THRONE 242 548
12 B 312 CONC 777 680
10 S 313 GEGS 240 712
7 C 265
8 S 315 GORN 923 981
14 C 207
14 B 317 GLIN 1722 766
0 B 318 AA 348 918
4 S 319 CAE 1446 852
2 C 194
10 B 321 STRIPE 941 27
1 C 261
11 S 323 STRIPE 1713 304
14 B 324 THRONE 229 862
6 B 325 CAE 812 495
2 B 326 THRONE 1629 181
4 B 327 GORN 511 362
3 S 328 GORN 587 816
3 B 329 AAO 195 56
14 C 178
5 S 331 AAIE 1249 246
5 B 332 GEGS 343 747
3 B 333 AAO 1524 704
3 C 227
10 B 335 GLIN 417 523
8 B 336 A 853 842
8 C 131
0 C 157
6 B 339 GORN 1383 139
12 B 340 FEG 1917 43
12 C 340
2 B 342 AAIN 1399 534
4 B 343 AAN 148 89
2 C 234
11 S 345 GORN 125 837
6 S 346 STRIPE 885 261
11 B 347 GORN 1315 929
13 S 348 VIDE 1916 814
3 S 349 HAHEOD 591 804
2 C 194
13 B 351 GLIN 409 254
11 C 282
12 B 353 GEGS 1951 757
0 B 354 AA 579 257
0 B 355 BDD 1563 508
9 B 356 CAE 1942 268
6 C 298
13 C 161
7 C 272
11 S 360 AAO 676 378
14 B 361 GORN 1849 819
13 B 362 CONC 1881 537
3 B 363 AAIN 938 630
4 S 364 AAM 549 157
11 C 151
9 C 356
10 S 367 CONC 1050 311
6 B 368 AAIE 1922 170
5 C 310
10 C 179
12 C 340
7 C 211
6 B 373 BDD 1147 362
14 C 226
10 C 171
2 S 376 AAID 1570 694
11 C 241
9 B 378 CONC 1106 922
13 S 379 AAC 1606 637
8 B 380 GORN 1526 599
14 C 226
4 S 382 GLIN 1382 471
12 S 383 CONC 1845 577
5 S 384 AAM 1057 353
14 B 385 BDD 850 564
2 C 218
4 C 259
7 C 269
1 S 389 AAIN 454 550
5 S 390 THRONE 1695 489
6 C 238
7 S 392 A 428 457
13 B 393 AAIC 1176 23
13 S 394 GORN 924 573
5 B 395 GORN 411 757
1 B 396 CAE 1294 840
12 C 305
4 S 398 AAC 1598 42
7 C 228
7 C 211
1 B 401 FEG 777 902
7 B 402 AAIE 1264 743
5 C 225
2 S 404 GLIN 911 569
3 C 363
9 B 406 A 772 709
5 C 168
12 C 217
14 B 409 AAN 1565 710
7 S 410 AAIC 1115 938
11 B 411 GORN 1293 655
7 C 228
8 S 413 VIDE 1766 184
9 S 414 GLIN 1715 106
0 C 354
3 S 416 A 1877 680
0 C 101
5 C 310
8 S 419 CAE 187 639
14 B 420 AA 1511 494
3 B 421 AAC 1117 854
7 S 422 AAIN 779 21
11 B 423 FEG 326 588
13 C 161
2 S 425 AAM 368 435
12 B 426 AAM 999 416
11 S 427 AAN 741 76
2 B 428 GORN 1579 78
13 S 429 GORN 1089 457
10 S 430 GORN 1241 959
9 B 431 A 1249 337
0 S 432 GORN 1781 357
11 B 433 GLIN 310 728
4 S 434 HAHEOD 1058 698
10 C 278
3 S 436 AA 1167 410
3 S 437 AA 1159 993
5 S 438 AA 358 271
2 S 439 STRA 1346 588
9 C 431
11 B 441 AA 785 284
6 C 107
14 B 443 VIDE 628 976
6 C 232
1 C 109
2 S 446 AAIC 346 237
0 B 447 AAID 865 140
5 C 331
14 B 449 AA 1799 823
11 C 147
0 C 447
0 B 452 STRIPE 749 885
12 C 124
10 B 454 GORN 1017 442
10 C 206
8 C 223
0 S 457 AAIC 1074 788
12 C 217
7 S 459 AAO 1448 431
14 C 260
7 B 461 GLIN 1680 867
11 S 462 AAN 1487 953
1 S 463 BDD 532 115
0 B 464 AAC 1958 31
8 B 465 THRONE 760 41
3 B 466 AAN 1042 701
14 C 260
11 S 468 GORN 1930 684
12 B 469 AAM 1536 637
9 B 470 THRONE 1724 509
6 B 471 AAIE 1822 197
6 C 368
3 B 473 HAHEOD 1524 11
7 B 474 VIDE 267 295
6 S 475 VIDE 1639 745
7 B 476 STRA 1668 938
14 B 477 GORN 1918 432
6 B 478 AAIE 1181 236
10 B 479 THRONE 1951 902
10 C 479
4 B 481 GLIN 324 294
13 B 482 STRA 1514 964
2 C 194
11 B 484 STRIPE 1200 947
10 C 430
8 C 106
1 C 463
7 C 265
12 C 305
9 B 490 CAE 1278 663
6 B 491 STRIPE 244 420
8 S 492 CONC 999 178
14 C 135
0 S 494 FEG 1631 234
0 C 355
10 S 496 AAO 963 404
10 S 497 AAN 378 452
12 B 498 AAN 905 751
7 C 461
14 S 500 A 1167 175
0 B 501 VIDE 1228 821
6 S 502 AAIC 126 751
9 C 122
11 B 504 HAHEOD 714 610
4 S 505 AA 153 236
4 C 152
14 S 507 GORN 1510 256
10 C 206
10 S 509 THRONE 233 307
6 C 293
8 C 315
2 C 428
0 C 110
1 B 514 CONC 1499 893
9 S 515 CAE 1149 991
4 S 516 GLIN 1143 591
4 S 517 GORN 547 444
5 B 518 GLIN 1244 263
2 C 446
13 C 351
14 B 521 AAN 827 809
6 C 475
9 B 523 STRIPE 630 915
7 S 524 THRONE 779 905
12 B 525 AAM 1667 906
9 C 470
14 B 527 CAE 1856 474
2 C 342
3 B 529 AAIC 1441 673
4 B 530 GORN 581 522
14 C 186
4 C 517
11 C 282
14 S 534 AAC 1570 213
0 C 157
8 B 536 STRA 1124 824
13 B 537 AAM 1144 937
6 C 238
9 B 539 THRONE 1371 927
13 C 140
10 C 430
2 S 542 A 1340 43
1 C 514
12 S 544 THRONE 352 992
9 S 545 CAE 1429 220
14 B 546 A 1552 553
8 B 547 GLIN 1832 846
9 S 548 AAM 947 717
11 S 549 GLIN 246 946
13 B 550 AAID 897 952
4 C 271
3 C 129
0 S 553 VIDE 142 944
10 S 554 AAID 176 360
0 B 555 BDD 1065 242
3 S 556 AA 1866 948
8 S 557 AA 1370 144
13 B 558 GLIN 492 262
6 B 559 AAO 811 411
3 B 560 AAN 1957 321
10 B 561 STRA 398 77
6 B 562 AAIE 1860 221
7 B 563 AA 258 613
12 C 217
0 C 464
7 C 461
7 S 567 STRA 899 816
14 B 568 GEGS 793 790
5 S 569 GEGS 134 873
11 S 570 HAHEOD 395 819
14 B 571 AAO 400 461
9 C 406
6 B 573 GORN 961 408
3 S 574 GLIN 1729 551
