tests/mediumHard/mediumHard_24.in
15
o
0 B 102 AAIE 220 655
10 S 103 AAIE 251 1000
0 S 104 THRONE 577 745
14 B 105 AAIC 1120 548
2 S 106 VIDE 1968 424
11 S 107 FEG 1944 402
10 C 103
14 C 105
3 B 111 VIDE 1606 406
1 B 112 BDD 598 845
2 B 113 AA 1703 915
10 C 103
2 B 115 AAID 1292 410
3 C 111
14 C 105
14 S 119 BDD 1633 80
10 S 120 AAIE 1612 853
1 C 112
3 S 122 STRA 1948 474
4 S 123 AAIN 535 364
6 S 124 HAHEOD 743 947
2 B 125 HAHEOD 1255 767
11 B 126 GLIN 460 252
6 B 128 VIDE 1583 61
4 C 123
14 S 130 DOOR 1024 39
0 S 131 STRA 1287 143
4 B 132 GORN 1704 145
0 S 134 A 286 127
13 B 135 AA 336 824
1 C 112
2 C 125
6 C 128
3 S 139 FEG 788 279
10 S 140 AAN 1544 335
6 S 141 HAHEOD 263 65
7 S 142 GLIN 1556 823
7 B 143 GEGS 1796 369
3 C 111
14 S 145 VIDE 493 368
0 C 102
8 S 147 AAC 893 807
13 S 148 A 1645 470
9 B 149 STRA 855 658
4 C 123
8 S 151 AAIE 888 777
0 C 104
3 C 111
8 S 154 AAID 1441 493
7 C 143
6 S 156 BDD 236 278
2 B 157 FEG 529 412
4 S 158 AA 526 100
9 B 159 CAE 853 855
9 B 160 AAID 313 370
1 C 112
12 S 162 GORN 760 275
13 C 148
3 B 164 AAIE 833 154
13 B 165 AAIC 1656 639
3 C 164
5 S 167 GORN 634 733
8 B 168 AAN 125 726
2 C 115
8 B 170 THRONE 771 840
5 B 171 GORN 960 288
5 B 172 AAM 318 416
10 C 103
9 C 149
6 C 156
3 S 176 VIDE 1318 788
14 C 119
9 C 149
12 S 179 GLIN 1286 430
1 C 112
12 C 162
10 C 103
1 B 183 GORN 1942 387
13 B 184 CONC 781 76
6 C 141
0 B 186 AAC 136 94
10 B 187 GORN 1190 418
6 B 188 VIDE 1640 35
2 B 189 STRA 952 889
12 S 190 AAIC 519 758
0 B 191 AAID 1006 43
11 C 126
14 S 193 CONC 609 383
7 S 194 AAN 299 107
10 B 195 CONC 194 822
0 S 196 GORN 1146 289
10 S 197 VIDE 1244 72
2 C 113
6 C 128
8 S 200 STRA 780 129
14 S 201 DOOR 1141 181
14 C 119
10 B 203 AAIE 1433 468
10 S 204 CONC 1140 952
4 S 205 VIDE 1415 191
5 S 206 THRONE 633 198
14 S 207 AAM 416 459
12 C 179
8 C 170
1 S 210 AA 233 152
9 B 211 CONC 168 42
5 C 167
1 C 210
3 S 214 HAHEOD 909 862
2 C 157
7 C 142
14 B 217 GLIN 714 459
6 B 218 AAO 1535 769
6 B 219 AAN 214 586
13 C 165
9 B 221 AAIN 616 770
3 S 222 AAO 454 919
10 C 197
3 S 224 HAHEOD 1888 970
14 C 217
12 S 226 AAIC 324 28
8 S 227 BDD 1228 874
7 C 143
10 B 229 GEGS 898 172
4 B 230 STRIPE 1413 30
4 C 230
13 B 232 BDD 1568 570
11 S 233 BDD 1497 384
6 C 141
2 S 235 AA 271 851
5 B 236 GLIN 897 945
2 C 113
3 B 238 AAN 1902 25
9 C 211
6 C 218
0 B 241 STRIPE 1231 493
2 B 242 STRIPE 573 700
7 B 243 AAIE 829 548
13 C 232
5 C 167
12 C 162
2 C 106
0 S 248 GLIN 1128 553
5 C 171
3 B 250 AAIE 536 218
11 C 126
2 B 252 FEG 220 829
2 C 242
1 C 183
9 B 255 VIDE 962 22
5 S 256 AA 1251 60
5 C 236
9 S 258 THRONE 514 127
0 S 259 AAO 862 296
10 B 260 FEG 1962 623
11 S 261 A 703 43
12 B 262 FEG 1885 69
13 B 263 AAIN 437 187
14 S 264 BDD 558 457
9 S 265 GEGS 775 382
5 S 266 VIDE 560 197
11 B 267 AA 847 830
8 S 268 GORN 698 417
9 C 221
9 S 270 AAIC 1097 526
9 S 271 STRA 853 751
5 S 272 AAM 1346 254
0 C 241
1 S 274 CAE 970 795
0 B 275 GORN 1496 837
1 C 112
10 B 277 GORN 1214 226
6 C 124
2 C 189
4 B 280 BDD 1144 72
6 S 281 THRONE 1388 324
1 C 210
10 S 283 STRA 966 372
11 S 284 THRONE 1569 377
10 B 285 VIDE 1554 30
11 S 286 FEG 1884 795
7 C 142
4 C 158
12 B 289 GEGS 1340 220
5 C 272
10 S 291 GEGS 772 387
11 B 292 AAC 937 347
5 S 293 FEG 944 409
0 S 294 GLIN 1319 873
0 C 275
8 B 296 AAM 736 910
3 S 297 DOOR 492 965
8 C 200
2 C 235
6 B 300 A 1810 190
6 S 301 STRIPE 542 639
13 S 302 AAIC 1780 308
5 B 303 GORN 594 492
5 B 304 VIDE 1814 401
1 C 210
8 C 147
7 S 307 BDD 357 257
4 S 308 FEG 777 478
9 S 309 HAHEOD 822 253
0 B 310 HAHEOD 541 261
3 B 311 GORN 1978 756
12 B 312 BDD 400 27
12 B 313 AAN 1893 587
5 S 314 STRIPE 411 142
3 C 297
6 S 316 A 386 737
0 C 186
2 B 318 AAC 1673 916
2 B 319 STRA 1945 817
14 C 130
4 C 280
4 B 322 FEG 443 345
10 C 187
11 S 324 AAM 893 624
2 C 115
5 C 304
8 B 327 HAHEOD 983 961
14 B 328 AAID 673 979
14 C 201
7 S 330 DOOR 867 386
11 B 331 HAHEOD 1235 963
1 B 332 STRIPE 494 310
12 C 179
13 S 334 AA 1726 346
7 S 335 THRONE 172 157
4 S 336 CONC 487 662
0 B 337 GEGS 1543 149
12 B 338 FEG 714 699
2 S 339 GEGS 626 830
6 C 301
0 B 341 GLIN 1637 596
7 S 342 AA 850 633
14 S 343 GLIN 285 30
4 C 132
11 C 233
14 C 217
7 C 194
8 C 147
1 B 349 A 566 869
10 B 350 AAIN 1606 457
3 S 351 GORN 1755 372
3 B 352 AAC 843 530
5 C 256
8 C 168
5 S 355 GORN 882 485
0 S 356 AAIC 1778 286
1 S 357 STRIPE 772 842
1 B 358 CONC 509 747
5 C 236
9 B 360 GEGS 372 682
1 B 361 STRIPE 442 940
4 B 362 AAC 903 99
1 S 363 AA 808 466
4 C 205
1 C 274
1 B 366 AAIE 152 375
5 C 266
6 C 300
5 B 369 CONC 1169 124
4 C 205
13 C 302
13 C 148
0 C 102
0 S 374 AAIN 1846 108
8 S 375 AAID 1510 963
0 C 294
0 C 294
5 C 171
12 B 379 A 294 71
8 B 380 GORN 301 590
10 B 381 A 1592 695
3 S 382 GEGS 757 101
6 S 383 STRIPE 955 728
3 C 224
0 S 385 AAO 1755 821
14 B 386 CONC 713 326
4 C 158
1 B 388 AAO 1684 176
3 C 297
3 B 390 AA 1094 412
14 B 391 AA 427 355
1 B 392 AAN 277 868
12 S 393 AAIE 459 406
13 B 394 CONC 1866 71
1 C 363
0 S 396 GORN 1966 309
1 B 397 BDD 284 489
3 C 250
11 S 399 AAIE 568 738
8 C 154
7 B 401 GORN 869 630
13 B 402 DOOR 379 527
11 C 324
3 C 214
1 S 405 AAO 353 593
3 S 406 CONC 911 473
14 B 407 CONC 793 412
13 C 148
9 B 409 AAIC 1735 499
0 C 241
1 S 411 GORN 136 496
6 S 412 CONC 1399 670
10 S 413 AAM 429 557
9 B 414 AAIN 1932 745
9 S 415 AAN 1257 13
9 B 416 AAIE 742 370
0 C 385
10 C 285
2 S 419 CONC 736 206
4 C 158
14 S 421 AAC 276 854
7 S 422 AAC 1795 462
9 C 160
6 C 188
2 B 425 GLIN 209 742
5 C 171
10 B 427 VIDE 1577 200
7 S 428 AAID 346 425
6 S 429 VIDE 252 429
3 C 224
14 B 431 BDD 1486 635
0 S 432 AA 645 171
9 C 270
12 S 434 CONC 1401 368
5 C 314
1 S 436 BDD 1921 982
12 S 437 CAE 1131 31
12 C 437
5 S 439 BDD 1061 157
7 B 440 FEG 1928 198
7 S 441 GORN 305 136
9 B 442 STRIPE 855 462
7 B 443 DOOR 746 991
8 B 444 CAE 862 953
7 C 401
1 C 411
12 S 447 AAIE 1771 576
9 S 448 AAIC 233 443
5 S 449 BDD 649 288
8 C 170
11 C 399
4 C 123
13 B 453 AAO 130 201
13 S 454 BDD 1078 830
11 S 455 STRIPE 1938 896
2 B 456 THRONE 1479 24
6 S 457 THRONE 1479 962
8 S 458 AAM 136 809
9 C 271
0 S 460 AAIN 1755 498
1 S 461 THRONE 1764 931
12 S 462 STRIPE 1530 79
0 B 463 AAM 1588 522
0 S 464 CAE 1427 826
13 C 135
10 C 120
7 C 307
10 C 197
14 B 469 AA 492 843
2 C 235
7 B 471 STRIPE 803 621
3 S 472 AAIC 1180 958
2 B 473 AA 204 458
6 S 474 STRIPE 1022 939
14 B 475 AAN 1974 579
9 S 476 VIDE 1376 925
13 S 477 AAIC 822 440
1 C 357
10 C 120
8 S 480 AAIC 1528 450
12 C 379
3 B 482 GORN 374 765
13 B 483 AAM 1518 695
5 C 272
0 C 134
4 S 486 AAIC 1770 876
8 B 487 GEGS 352 385
11 S 488 AA 976 190
6 S 489 GEGS 624 903
3 B 490 GORN 1811 561
14 B 491 AAC 1065 655
5 C 236
13 C 394
3 B 494 CAE 1890 40
14 C 475
12 B 496 AAM 1961 883
9 C 409
13 S 498 STRIPE 688 274
6 S 499 STRA 1026 413
10 S 500 AAM 1366 557
2 B 501 CONC 457 912
12 S 502 VIDE 883 910
5 B 503 STRA 1758 555
11 B 504 A 753 868
4 B 505 CONC 597 866
7 S 506 GLIN 583 865
12 S 507 DOOR 1875 795
1 S 508 FEG 296 998
10 S 509 STRA 741 141
5 S 510 THRONE 1211 178
10 S 511 GORN 1394 608
12 B 512 VIDE 1148 537
6 S 513 BDD 1322 425
14 B 514 AAIC 955 591
12 C 179
6 B 516 AAID 1503 819
4 S 517 AA 1218 515
3 S 518 AAC 973 158
9 S 519 AA 1830 470
2 S 520 DOOR 1628 491
0 B 521 CONC 764 168
9 C 360
6 B 523 FEG 1193 324
5 C 439
10 C 103
7 B 526 THRONE 1739 905
7 C 526
11 S 528 DOOR 1767 947
3 S 529 AAIC 553 471
2 B 530 AAIC 214 55
5 C 272
6 S 532 STRIPE 419 625
10 C 187
8 S 534 GLIN 1457 171
3 S 535 DOOR 1307 232
8 C 380
6 C 499
2 B 538 GORN 1225 906
8 B 539 AAIN 1215 446
9 C 270
0 S 541 AA 453 198
10 B 542 A 1538 22
12 C 190
14 C 431
11 C 286
12 C 502
7 S 547 STRA 1006 364
11 S 548 CONC 1860 399
5 S 549 BDD 1793 324
4 S 550 VIDE 416 499
6 C 457
8 S 552 AAID 1745 620
3 S 553 THRONE 278 158
4 C 322
1 C 436
1 C 112
11 B 557 AA 977 441
11 C 399
7 S 559 DOOR 208 337
1 C 366
14 C 421
11 B 562 AAIE 334 24
2 B 563 VIDE 1377 80
9 B 564 AAIE 1673 398
4 C 322
10 C 285
9 C 416
4 S 568 FEG 936 736
1 S 569 AAIE 727 212
13 B 570 HAHEOD 396 532
7 B 571 THRONE 1840 570
1 S 572 STRA 1589 280
11 S 573 FEG 1399 188
1 C 405
11 B 575 AA 970 869
11 B 576 AAID 1354 56
10 C 277
11 C 292
9 B 579 BDD 171 692
5 S 580 BDD 1960 162
0 B 581 AAN 1395 41
